ERROR:root:2024-04-29 14:51:43: Exception occurred at   File "C:\Users\CWhite\CODE\PythonCode\SalesforceLive\pub-sub-api\python\PubSubAPIClient.py", line 145, in <module>
    raise Exception("Error testing")
: Error testing
ERROR:root:2024-04-29 17:50:24: Exception occurred at   File "C:\Users\CWhite\CODE\PythonCode\SalesforceLive\pub-sub-api\python\PubSubAPIClient.py", line 150, in <module>
    raise Exception("Test error")
: Test error
ERROR:root:2024-04-29 17:51:54: Exception occurred at   File "C:\Users\CWhite\CODE\PythonCode\SalesforceLive\pub-sub-api\python\PubSubAPIClient.py", line 150, in <module>
    raise Exception("Test error")
: Test error
ERROR:root:2024-05-01 08:11:03: AttributeError occurred at   File "C:\Users\CWhite\CODE\PythonCode\SalesforceLive\pub-sub-api\python\refreshTableauData.py", line 160, in eventTransform
    if not dfTransformE.empty:
           ^^^^^^^^^^^^^^^^^^
: 'NoneType' object has no attribute 'empty'
ERROR:root:2024-05-01 08:13:49: AttributeError occurred at   File "C:\Users\CWhite\CODE\PythonCode\SalesforceLive\pub-sub-api\python\refreshTableauData.py", line 160, in eventTransform
    if not dfTransformE.empty:
           ^^^^^^^^^^^^^^^^^^
: 'NoneType' object has no attribute 'empty'
ERROR:root:2024-05-02 16:09:40: KeyError occurred at   File "C:\Users\CWhite\CODE\PythonCode\SalesforceLive\pub-sub-api\python\refreshTableauData.py", line 116, in eventColleagueDataRequest
    event_colleague_data = dataEC['data']['uiapi']['query']['Event_Colleague__c']['edges']
                           ~~~~~~~~~~~~~~^^^^^^^^^
: 'uiapi'
ERROR:root:2024-05-03 11:00:59: _MultiThreadedRendezvous occurred at   File "C:\Users\CWhite\CODE\PythonCode\SalesforceLive\venv\Lib\site-packages\grpc\_channel.py", line 951, in _next
    raise self
: <_MultiThreadedRendezvous of RPC that terminated with:
	status = StatusCode.INTERNAL
	details = "Received RST_STREAM with error code 0"
	debug_error_string = "UNKNOWN:Error received from peer ipv4:18.132.223.115:7443 {grpc_message:"Received RST_STREAM with error code 0", grpc_status:13, created_time:"2024-05-03T10:00:56.7493207+00:00"}"
>
ERROR:root:2024-05-03 11:52:07: _MultiThreadedRendezvous occurred at   File "C:\Users\CWhite\CODE\PythonCode\SalesforceLive\venv\Lib\site-packages\grpc\_channel.py", line 968, in _next
    raise self
: <_MultiThreadedRendezvous of RPC that terminated with:
	status = StatusCode.INTERNAL
	details = "Received RST_STREAM with error code 0"
	debug_error_string = "UNKNOWN:Error received from peer ipv4:13.42.182.75:7443 {created_time:"2024-05-03T10:52:04.2365107+00:00", grpc_status:13, grpc_message:"Received RST_STREAM with error code 0"}"
>
ERROR:root:2024-05-03 16:24:38: _MultiThreadedRendezvous occurred at   File "C:\Users\CWhite\CODE\PythonCode\SalesforceLive\venv\Lib\site-packages\grpc\_channel.py", line 968, in _next
    raise self
: <_MultiThreadedRendezvous of RPC that terminated with:
	status = StatusCode.INTERNAL
	details = "Received RST_STREAM with error code 0"
	debug_error_string = "UNKNOWN:Error received from peer ipv4:18.134.171.43:7443 {created_time:"2024-05-03T15:24:37.9312673+00:00", grpc_status:13, grpc_message:"Received RST_STREAM with error code 0"}"
>
ERROR:root:2024-05-03 21:42:37: _MultiThreadedRendezvous occurred at   File "C:\Users\CWhite\CODE\PythonCode\SalesforceLive\venv\Lib\site-packages\grpc\_channel.py", line 968, in _next
    raise self
: <_MultiThreadedRendezvous of RPC that terminated with:
	status = StatusCode.INTERNAL
	details = "Received RST_STREAM with error code 0"
	debug_error_string = "UNKNOWN:Error received from peer ipv4:18.132.223.115:7443 {created_time:"2024-05-03T20:42:37.1442486+00:00", grpc_status:13, grpc_message:"Received RST_STREAM with error code 0"}"
>
ERROR:root:2024-05-05 12:04:51: AttributeError occurred at   File "C:\Users\CWhite\CODE\PythonCode\SalesforceLive\pub-sub-api\python\refreshTableauData.py", line 185, in eventTransform
    if not dfTransformE.empty:
           ^^^^^^^^^^^^^^^^^^
: 'NoneType' object has no attribute 'empty'
ERROR:root:2024-05-05 12:16:52: AttributeError occurred at   File "C:\Users\CWhite\CODE\PythonCode\SalesforceLive\pub-sub-api\python\refreshTableauData.py", line 185, in eventTransform
    if not dfTransformE.empty:
           ^^^^^^^^^^^^^^^^^^
: 'NoneType' object has no attribute 'empty'
ERROR:root:2024-05-05 12:19:11: AttributeError occurred at   File "C:\Users\CWhite\CODE\PythonCode\SalesforceLive\pub-sub-api\python\refreshTableauData.py", line 185, in eventTransform
    if not dfTransformE.empty:
           ^^^^^^^^^^^^^^^^^^
: 'NoneType' object has no attribute 'empty'
ERROR:root:2024-05-05 12:35:01: AttributeError occurred at   File "C:\Users\CWhite\CODE\PythonCode\SalesforceLive\pub-sub-api\python\refreshTableauData.py", line 189, in eventTransform
    if not dfTransformE.empty:
           ^^^^^^^^^^^^^^^^^^
: 'NoneType' object has no attribute 'empty'
ERROR:root:2024-05-05 12:52:00: AttributeError occurred at   File "C:\Users\CWhite\CODE\PythonCode\SalesforceLive\pub-sub-api\python\refreshTableauData.py", line 185, in eventTransform
    if not dfTransformE.empty:
           ^^^^^^^^^^^^^^^^^^
: 'NoneType' object has no attribute 'empty'
ERROR:root:2024-05-05 13:04:13: AttributeError occurred at   File "C:\Users\CWhite\CODE\PythonCode\SalesforceLive\pub-sub-api\python\refreshTableauData.py", line 185, in eventTransform
    if not dfTransformE.empty:
           ^^^^^^^^^^^^^^^^^^
: 'NoneType' object has no attribute 'empty'
ERROR:root:2024-05-05 14:24:46: AttributeError occurred at   File "C:\Users\CWhite\CODE\PythonCode\SalesforceLive\pub-sub-api\python\refreshTableauData.py", line 186, in eventTransform
    if not dfTransformE.empty:
           ^^^^^^^^^^^^^^^^^^
: 'NoneType' object has no attribute 'empty'
ERROR:root:2024-05-05 14:26:41: AttributeError occurred at   File "C:\Users\CWhite\CODE\PythonCode\SalesforceLive\pub-sub-api\python\refreshTableauData.py", line 186, in eventTransform
    if not dfTransformE.empty:
           ^^^^^^^^^^^^^^^^^^
: 'NoneType' object has no attribute 'empty'
ERROR:root:2024-05-05 14:27:43: AttributeError occurred at   File "C:\Users\CWhite\CODE\PythonCode\SalesforceLive\pub-sub-api\python\refreshTableauData.py", line 186, in eventTransform
    if not dfTransformE.empty:
           ^^^^^^^^^^^^^^^^^^
: 'NoneType' object has no attribute 'empty'
ERROR:root:2024-05-05 14:35:26: AttributeError occurred at   File "C:\Users\CWhite\CODE\PythonCode\SalesforceLive\pub-sub-api\python\refreshTableauData.py", line 180, in eventTransform
    if not dfTransformE.empty:
           ^^^^^^^^^^^^^^^^^^
: 'NoneType' object has no attribute 'empty'
ERROR:root:2024-05-05 14:39:37: Exception occurred at   File "C:\Users\CWhite\CODE\PythonCode\SalesforceLive\pub-sub-api\python\refreshTableauData.py", line 82, in eventDataRequest
    raise Exception("Error:", responseE.text)
: ('Error:', '[{"message":"Session expired or invalid","errorCode":"INVALID_SESSION_ID"}]')
ERROR:root:2024-05-05 14:56:01: NameError occurred at   File "C:\Users\CWhite\CODE\PythonCode\SalesforceLive\pub-sub-api\python\PubSubAPIClient.py", line 26, in <module>
    if expired_error:
       ^^^^^^^^^^^^^
: name 'expired_error' is not defined
ERROR:root:2024-05-05 14:56:38: Exception occurred at   File "C:\Users\CWhite\CODE\PythonCode\SalesforceLive\pub-sub-api\python\refreshTableauData.py", line 80, in eventDataRequest
    raise Exception("Error gathering Event data:", responseE.text)
: ('Error gathering Event data:', '[{"message":"Session expired or invalid","errorCode":"INVALID_SESSION_ID"}]')
ERROR:root:2024-05-05 14:57:39: Exception occurred at   File "C:\Users\CWhite\CODE\PythonCode\SalesforceLive\pub-sub-api\python\refreshTableauData.py", line 80, in eventDataRequest
    raise Exception("Error gathering Event data:", responseE.text)
: ('Error gathering Event data:', '[{"message":"Session expired or invalid","errorCode":"INVALID_SESSION_ID"}]')
